<?xml version="1.0"?>
<robot name="legrobot">

  <link name="base_link">
    <inertial>
      <origin xyz="-0.24659 0 0" rpy="0 0 0"/>
      <mass value="505.3"/>
      <inertia ixx="180.49" ixy="-1.7051E-16" ixz="3.1238E-33"
               iyy="21.405" iyz="-3.015E-33" izz="181.05"/>
    </inertial>
    <visual>
      <origin xyz="0 0 0" rpy="0 0 0"/>
      <geometry>
        <mesh filename="package://lesson_urdf/meshes/base_link.STL"/>
      </geometry>
    </visual>
    <collision>
      <origin xyz="0 0 0" rpy="0 0 0"/>
      <geometry>
        <mesh filename="package://lesson_urdf/meshes/base_link.STL"/>
      </geometry>
    </collision>
  </link>

  <link name="Link_c_right">
    <inertial>
      <origin xyz="5.3301E-06 0.0038754 0.25388" rpy="0 0 0"/>
      <mass value="119.7"/>
      <inertia ixx="5.025" ixy="0.00011583" ixz="2.4725E-06"
               iyy="5.1092" iyz="0.0017977" izz="5.1092"/>
    </inertial>
    <visual>
      <origin xyz="0 0 0" rpy="0 0 0"/>
      <geometry>
        <mesh filename="package://lesson_urdf/meshes/Link_c_right.STL"/>
      </geometry>
    </visual>
    <collision>
      <origin xyz="0 0 0" rpy="0 0 0"/>
      <geometry>
        <mesh filename="package://lesson_urdf/meshes/Link_c_right.STL"/>
      </geometry>
    </collision>
  </link>

  <joint name="Joint_c_right" type="revolute">
    <origin xyz="0 -0.8 0" rpy="1.5708 0 1.5708"/>
    <parent link="base_link"/>
    <child link="Link_c_right"/>
    <axis xyz="0 0 1"/>
    <limit lower="-1.5708" upper="1.5708" effort="100" velocity="5"/>
    <dynamics damping="0.1" friction="0.1"/>
  </joint>

  <link name="Link_p_right">
    <inertial>
      <origin xyz="0 0.8 0.39728" rpy="0 0 0"/>
      <mass value="505.3"/>
      <inertia ixx="181.05" ixy="-4.2088E-16" ixz="-1.3878E-17"
               iyy="21.405" iyz="4.3426E-16" izz="180.49"/>
    </inertial>
    <visual>
      <origin xyz="0 0 0" rpy="0 0 0"/>
      <geometry>
        <mesh filename="package://lesson_urdf/meshes/Link_p_right.STL"/>
      </geometry>
    </visual>
    <collision>
      <origin xyz="0 0 0" rpy="0 0 0"/>
      <geometry>
        <mesh filename="package://lesson_urdf/meshes/Link_p_right.STL"/>
      </geometry>
    </collision>
  </link>

  <joint name="Joint_p_right" type="revolute">
    <origin xyz="-0.00013659 -0.099312 0.25" rpy="1.5708 0 -0.0013754"/>
    <parent link="Link_c_right"/>
    <child link="Link_p_right"/>
    <axis xyz="0 0 1"/>
    <limit lower="-1.5708" upper="1.5708" effort="100" velocity="5"/>
    <dynamics damping="0.1" friction="0.1"/>
  </joint>

  <link name="Link_r_right">
    <inertial>
      <origin xyz="-2.2204E-16 -0.80426 0.10025" rpy="0 0 0"/>
      <mass value="497.35"/>
      <inertia ixx="175.29" ixy="1.5666E-15" ixz="2.0817E-16"
               iyy="20.743" iyz="-0.37308" izz="175.37"/>
    </inertial>
    <visual>
      <origin xyz="0 0 0" rpy="0 0 0"/>
      <geometry>
        <mesh filename="package://lesson_urdf/meshes/Link_r_right.STL"/>
      </geometry>
    </visual>
    <collision>
      <origin xyz="0 0 0" rpy="0 0 0"/>
      <geometry>
        <mesh filename="package://lesson_urdf/meshes/Link_r_right.STL"/>
      </geometry>
    </collision>
  </link>

  <joint name="Joint_r_right" type="revolute">
    <origin xyz="0 1.6 0" rpy="3.1416 0 0"/>
    <parent link="Link_p_right"/>
    <child link="Link_r_right"/>
    <axis xyz="0 0 1"/>
    <limit lower="-1.5708" upper="1.5708" effort="100" velocity="5"/>
    <dynamics damping="0.1" friction="0.1"/>
  </joint>

  <link name="Link_c_left">
    <inertial>
      <origin xyz="5.3301E-06 0.0038754 0.25388" rpy="0 0 0"/>
      <mass value="119.7"/>
      <inertia ixx="5.025" ixy="0.00011583" ixz="2.4725E-06"
               iyy="5.1092" iyz="0.0017977" izz="5.1092"/>
    </inertial>
    <visual>
      <origin xyz="0 0 0" rpy="0 0 0"/>
      <geometry>
        <mesh filename="package://lesson_urdf/meshes/Link_c_left.STL"/>
      </geometry>
    </visual>
    <collision>
      <origin xyz="0 0 0" rpy="0 0 0"/>
      <geometry>
        <mesh filename="package://lesson_urdf/meshes/Link_c_left.STL"/>
      </geometry>
    </collision>
  </link>

  <joint name="Joint_c_left" type="revolute">
    <origin xyz="0 0.8 0" rpy="1.5708 0 1.5708"/>
    <parent link="base_link"/>
    <child link="Link_c_left"/>
    <axis xyz="0 0 1"/>
    <limit lower="-1.5708" upper="1.5708" effort="100" velocity="5"/>
    <dynamics damping="0.1" friction="0.1"/>
  </joint>

  <link name="Link_p_left">
    <inertial>
      <origin xyz="0 0.8 0.39728" rpy="0 0 0"/>
      <mass value="505.3"/>
      <inertia ixx="181.05" ixy="-4.4218E-15" ixz="-2.498E-16"
               iyy="21.405" iyz="-1.0268E-14" izz="180.49"/>
    </inertial>
    <visual>
      <origin xyz="0 0 0" rpy="0 0 0"/>
      <geometry>
        <mesh filename="package://lesson_urdf/meshes/Link_p_left.STL"/>
      </geometry>
    </visual>
    <collision>
      <origin xyz="0 0 0" rpy="0 0 0"/>
      <geometry>
        <mesh filename="package://lesson_urdf/meshes/Link_p_left.STL"/>
      </geometry>
    </collision>
  </link>

  <joint name="Joint_p_left" type="revolute">
    <origin xyz="-0.00013659 -0.099312 0.25" rpy="1.5708 0 -0.0013754"/>
    <parent link="Link_c_left"/>
    <child link="Link_p_left"/>
    <axis xyz="0 0 1"/>
    <limit lower="-1.5708" upper="1.5708" effort="100" velocity="5"/>
    <dynamics damping="0.1" friction="0.1"/>
  </joint>

  <link name="Link_r_left">
    <inertial>
      <origin xyz="0 -0.80426 0.10025" rpy="0 0 0"/>
      <mass value="497.35"/>
      <inertia ixx="175.29" ixy="-2.717E-16" ixz="2.0123E-15"
               iyy="20.743" iyz="-0.37308" izz="175.37"/>
    </inertial>
    <visual>
      <origin xyz="0 0 0" rpy="0 0 0"/>
      <geometry>
        <mesh filename="package://lesson_urdf/meshes/Link_r_left.STL"/>
      </geometry>
    </visual>
    <collision>
      <origin xyz="0 0 0" rpy="0 0 0"/>
      <geometry>
        <mesh filename="package://lesson_urdf/meshes/Link_r_left.STL"/>
      </geometry>
    </collision>
  </link>

  <joint name="Joint_r_left" type="revolute">
    <origin xyz="0 1.6 0" rpy="-3.1416 0 0"/>
    <parent link="Link_p_left"/>
    <child link="Link_r_left"/>
    <axis xyz="0 0 1"/>
    <limit lower="-1.5708" upper="1.5708" effort="100" velocity="5"/>
    <dynamics damping="0.1" friction="0.1"/>
  </joint>

</robot>